Workbook

Sheet Resumen
A1: Resumen del business case · Red de Confianza
A2: ROI = (Σ EBITDA 3 años − Inversión) / Inversión · VAN y TIR sobre flujos netos de 3 años sin valor terminal · Payback = meses hasta flujo acumulado ≥ 0.
A4: Indicador | B4: Conservador | C4: Base | D4: Optimista
A5: TAM: personas 60+ (2025) | B5: =Supuestos!$C$5 -> 8000000 | C5: =Supuestos!$D$5 -> 8000000 | D5: =Supuestos!$E$5 -> 8000000
A6: SAM: 60+ con tarjeta activa | B6: =Supuestos!$C$6 -> 3000000 | C6: =Supuestos!$D$6 -> 3500000 | D6: =Supuestos!$E$6 -> 4000000
A7: SOM: tarjetas 60+ en emisores Credibanco | B7: =Modelo!C4 -> 1050000 | C7: =Modelo!C22 -> 1400000 | D7: =Modelo!C40 -> 1600000
A8: Tarjetas cubiertas · Año 3 | B8: =Modelo!E5 -> 262500 | C8: =Modelo!E23 -> 560000 | D8: =Modelo!E41 -> 800000
A9: Tarjetas inscritas · Año 3 | B9: =Modelo!E6 -> 26250 | C9: =Modelo!E24 -> 78400 | D9: =Modelo!E42 -> 144000
A10: Ingresos · Año 3 (COP) | B10: =Modelo!E10 -> 975240000 | C10: =Modelo!E28 -> 2978304000 | D10: =Modelo!E46 -> 5713920000
A11: EBITDA · Año 3 (COP) | B11: =Modelo!E14 -> -58260000 | C11: =Modelo!E32 -> 1585984000 | D11: =Modelo!E50 -> 3862720000
A12: Margen EBITDA · Año 3 | B12: =Modelo!E15 -> -0.059739141 | C12: =Modelo!E33 -> 0.53251246 | D12: =Modelo!E51 -> 0.67601927
A13: Inversión inicial (COP) | B13: =Supuestos!$C$21 -> 920000000 | C13: =Supuestos!$D$21 -> 800000000 | D13: =Supuestos!$E$21 -> 720000000
A14: Flujo acumulado 3 años (COP) | B14: =Modelo!E18 -> -1581148320 | C14: =Modelo!E36 -> 1194560000 | D14: =Modelo!E54 -> 4689552000
A15: ROI a 3 años | B15: =(SUM(Modelo!C14:E14)-Supuestos!$C$21)/Supuestos!$C$21 -> -1.7186395 | C15: =(SUM(Modelo!C32:E32)-Supuestos!$D$21)/Supuestos!$D$21 -> 1.4932 | D15: =(SUM(Modelo!C50:E50)-Supuestos!$E$21)/Supuestos!$E$21 -> 6.5132667
A16: VAN @ tasa de descuento (COP) | B16: =SUM(Modelo!C19:E19) -> -1.3257615e+09 | C16: =SUM(Modelo!C37:E37) -> 6.3307291e+08 | D16: =SUM(Modelo!C55:E55) -> 3.070836e+09
A17: TIR | B17: =IFERROR(IRR(Modelo!C17:E17),"n.a.") -> n.a. | C17: =IFERROR(IRR(Modelo!C35:E35),"n.a.") -> 0.59876872 | D17: =IFERROR(IRR(Modelo!C53:E53),"n.a.") -> 2.3745584
A18: Payback (meses) | B18: =IF(Modelo!E18<0,"No recupera en 36",IF(Modelo!D18>=0,12+12*(-Modelo!C18)/Modelo!D17,24+12*(-Modelo!D18)/Modelo!E17)) -> No recupera en 36 | C18: =IF(Modelo!E36<0,"No recupera en 36",IF(Modelo!D36>=0,12+12*(-Modelo!C36)/Modelo!D35,24+12*(-Modelo!D36)/Modelo!E35)) -> 26.961624 | D18: =IF(Modelo!E54<0,"No recupera en 36",IF(Modelo!D54>=0,12+12*(-Modelo!C54)/Modelo!D53,24+12*(-Modelo!D54)/Modelo!E53)) -> 18.012398
A19: Punto de equilibrio Año 3 (tarjetas cubiertas) | B19: =Supuestos!$C$24/((Supuestos!$C$14-Supuestos!$C$19)*12+Supuestos!$C$13*((Supuestos!$C$15-Supuestos!$C$20)*12+Supuestos!$C$16*Supuestos!$C$17*12*Supuestos!$C$18)) -> 284608.38 | C19: =Supuestos!$D$24/((Supuestos!$D$14-Supuestos!$D$19)*12+Supuestos!$D$13*((Supuestos!$D$15-Supuestos!$D$20)*12+Supuestos!$D$16*Supuestos!$D$17*12*Supuestos!$D$18)) -> 168050.61 | D19: =Supuestos!$E$24/((Supuestos!$E$14-Supuestos!$E$19)*12+Supuestos!$E$13*((Supuestos!$E$15-Supuestos!$E$20)*12+Supuestos!$E$16*Supuestos!$E$17*12*Supuestos!$E$18)) -> 119752.04
A20: Punto de equilibrio como % del SOM | B20: =B19/B7 -> 0.2710556 | C20: =C19/C7 -> 0.12003615 | D20: =D19/D7 -> 0.074845027
A21: Precio mínimo Escudo para VAN = 0 (COP/tarjeta/mes) | B21: =Supuestos!$C$14-SUM(Modelo!C19:E19)/(Modelo!C5*Supuestos!$C$25/(1+Supuestos!$C$28)^1+Modelo!D5*Supuestos!$C$26/(1+Supuestos!$C$28)^2+Modelo!E5*Supuestos!$C$27/(1+Supuestos!$C$28)^3) -> 567.26191 | C21: =Supuestos!$D$14-SUM(Modelo!C37:E37)/(Modelo!C23*Supuestos!$D$25/(1+Supuestos!$D$28)^1+Modelo!D23*Supuestos!$D$26/(1+Supuestos!$D$28)^2+Modelo!E23*Supuestos!$D$27/(1+Supuestos!$D$28)^3) -> 169.22814 | D21: =Supuestos!$E$14-SUM(Modelo!C55:E55)/(Modelo!C41*Supuestos!$E$25/(1+Supuestos!$E$28)^1+Modelo!D41*Supuestos!$E$26/(1+Supuestos!$E$28)^2+Modelo!E41*Supuestos!$E$27/(1+Supuestos!$E$28)^3) -> 23.66579
A23: VAN esperado (ponderación 25% / 50% / 25%) | C23: =0.25*B16+0.5*C16+0.25*D16 -> 7.5280507e+08
A24: Pérdida máxima si se detiene en el gate del piloto (inversión + ~1 mes de operación) | B24: =Supuestos!$C$21+Supuestos!$C$22/5 -> 980000000 | C24: =Supuestos!$D$21+Supuestos!$D$22/5 -> 854000000 | D24: =Supuestos!$E$21+Supuestos!$E$22/5 -> 774000000
A26: Dictamen: APROBADO CON CONDICIONES — financiar discovery + MVP + piloto (≈COP 0,8–0,9 mil millones) y decidir escalamiento con los kill criteria del piloto.

Sheet Supuestos
A1: Business case · Red de Confianza (Silver Economy) · Supuestos
A2: Cifras en pesos colombianos (COP). Periodo base de población y precios: 2025. Año 1 = primeros 12 meses del roadmap. Texto azul = supuesto editable; celdas amarillas = supuestos críticos a validar en discovery.
A4: Supuesto | B4: Unidad | C4: Conservador | D4: Base | E4: Optimista | F4: Fuente / lógica
A5: TAM: personas de 60+ en Colombia (2025) | B5: personas | C5: 8000000 | D5: 8000000 | E5: 8000000 | F5: DANE, proyecciones CNPV 2018: 60+ ≈15,5% de la población en 2024 (2021: 7,1 M, 13,9%). Redondeado a 8,0 M para 2025.
A6: SAM: personas 60+ con tarjeta débito/crédito activa | B6: personas | C6: 3000000 | D6: 3500000 | E6: 4000000 | F6: Supuesto. Ancla: 2,11 M pensionados (SFC 2024) con mesada en cuenta + 60+ bancarizados con ingresos. RIF 2024: 65+ es el grupo con menor uso de depósitos. Validar con datos de emisores.
A7: Participación de tarjetas de emisores clientes de Credibanco | B7: % | C7: 0.35 | D7: 0.4 | E7: 0.4 | F7: Supuesto (no hay dato público de participación). Validar con el área comercial: emisores procesados por Credibanco.
A8: Cobertura: % del SOM en emisores que contratan · Año 1 | B8: % | C8: 0.03 | D8: 0.05 | E8: 0.08 | F8: Año 1 = piloto con 1 emisor + primeras ventas.
A9: Cobertura · Año 2 | B9: % | C9: 0.15 | D9: 0.25 | E9: 0.3 | F9: Ritmo de firma de emisores (ciclo de venta B2B 6–9 meses).
A10: Cobertura · Año 3 | B10: % | C10: 0.25 | D10: 0.4 | E10: 0.5
A11: Inscripción al Círculo de Confianza (% de tarjetas cubiertas) · Año 1 | B11: % | C11: 0.03 | D11: 0.04 | E11: 0.05 | F11: Opt-in asistido (oficina, línea, WhatsApp). Hipótesis H1 del piloto.
A12: Inscripción · Año 2 | B12: % | C12: 0.07 | D12: 0.1 | E12: 0.12
A13: Inscripción · Año 3 | B13: % | C13: 0.1 | D13: 0.14 | E13: 0.18
A14: Precio Escudo Senior (cobrado al emisor) | B14: COP/tarjeta cubierta/mes | C14: 200 | D14: 250 | E14: 300 | F14: Supuesto de precio por valor: ahorro estimado en fraude ≈ 1,5x el precio (hoja Valor_emisor). Validar disposición a pagar (H4).
A15: Precio Círculo de Confianza (cobrado al emisor) | B15: COP/tarjeta inscrita/mes | C15: 1000 | D15: 1200 | E15: 1400 | F15: ≈10% de una cuota de manejo de débito. Validar disposición a pagar (H4).
A16: Gasto mensual con tarjeta de una persona inscrita | B16: COP/mes | C16: 600000 | D16: 600000 | E16: 600000 | F16: Supuesto. Validar con datos transaccionales del emisor piloto.
A17: Aumento del gasto con tarjeta tras inscribirse (migración desde efectivo) | B17: % | C17: 0.08 | D17: 0.15 | E17: 0.2 | F17: Hipótesis H3. Contexto: el efectivo es ≈78% de las transacciones (BanRep).
A18: Ingreso neto de Credibanco sobre el valor incremental procesado | B18: % | C18: 0.002 | D18: 0.002 | E18: 0.002 | F18: Supuesto conservador de ingreso neto de red/adquirencia. Validar con Finanzas.
A19: Costo variable Escudo (cómputo + verificaciones) | B19: COP/tarjeta cubierta/mes | C19: 50 | D19: 50 | E19: 50 | F19: Supuesto.
A20: Costo variable Círculo (≈5 alertas WhatsApp/SMS + soporte) | B20: COP/tarjeta inscrita/mes | C20: 400 | D20: 400 | E20: 400 | F20: Supuesto: ≈COP 60 por mensaje + soporte.
A21: Inversión inicial (discovery, MVP, integración, legal, piloto) | B21: COP | C21: 920000000 | D21: 800000000 | E21: 720000000 | F21: Squad ~7 meses (≈COP 85 M/mes) + infraestructura, legal y piloto. Conservador +15%, optimista −10%.
A22: Costos fijos de operación · Año 1 (meses posteriores al MVP) | B22: COP | C22: 300000000 | D22: 270000000 | E22: 270000000 | F22: Equipo de operación ≈COP 53 M/mes + infraestructura y cumplimiento.
A23: Costos fijos · Año 2 | B23: COP | C23: 700000000 | D23: 640000000 | E23: 640000000
A24: Costos fijos · Año 3 | B24: COP | C24: 750000000 | D24: 680000000 | E24: 680000000
A25: Meses facturables · Año 1 | B25: meses | C25: 4 | D25: 4 | E25: 4 | F25: El piloto (meses 5–7) no se cobra; la facturación empieza en el mes 9.
A26: Meses facturables · Año 2 | B26: meses | C26: 12 | D26: 12 | E26: 12
A27: Meses facturables · Año 3 | B27: meses | C27: 12 | D27: 12 | E27: 12
A28: Tasa de descuento | B28: % | C28: 0.15 | D28: 0.15 | E28: 0.15 | F28: Supuesto de costo de capital de referencia. Validar con Finanzas.

Sheet Modelo
A1: Modelo por escenario · COP
A3: Escenario Conservador | C3: Año 1 | D3: Año 2 | E3: Año 3
A4: SOM: tarjetas 60+ en emisores Credibanco | C4: =Supuestos!$C$6*Supuestos!$C$7 -> 1050000 | D4: =Supuestos!$C$6*Supuestos!$C$7 -> 1050000 | E4: =Supuestos!$C$6*Supuestos!$C$7 -> 1050000
A5: Tarjetas cubiertas por Escudo | C5: =C4*Supuestos!$C$8 -> 31500 | D5: =D4*Supuestos!$C$9 -> 157500 | E5: =E4*Supuestos!$C$10 -> 262500
A6: Tarjetas inscritas en Círculo | C6: =C5*Supuestos!$C$11 -> 945 | D6: =D5*Supuestos!$C$12 -> 11025 | E6: =E5*Supuestos!$C$13 -> 26250
A7: Ingreso Escudo | C7: =C5*Supuestos!$C$14*Supuestos!$C$25 -> 25200000 | D7: =D5*Supuestos!$C$14*Supuestos!$C$26 -> 378000000 | E7: =E5*Supuestos!$C$14*Supuestos!$C$27 -> 630000000
A8: Ingreso Círculo | C8: =C6*Supuestos!$C$15*Supuestos!$C$25 -> 3780000 | D8: =D6*Supuestos!$C$15*Supuestos!$C$26 -> 132300000 | E8: =E6*Supuestos!$C$15*Supuestos!$C$27 -> 315000000
A9: Ingreso transaccional incremental | C9: =C6*Supuestos!$C$16*Supuestos!$C$17*Supuestos!$C$25*Supuestos!$C$18 -> 362880 | D9: =D6*Supuestos!$C$16*Supuestos!$C$17*Supuestos!$C$26*Supuestos!$C$18 -> 12700800 | E9: =E6*Supuestos!$C$16*Supuestos!$C$17*Supuestos!$C$27*Supuestos!$C$18 -> 30240000
A10: Ingresos totales | C10: =SUM(C7:C9) -> 29342880 | D10: =SUM(D7:D9) -> 523000800 | E10: =SUM(E7:E9) -> 975240000
A11: Costos variables | C11: =C5*Supuestos!$C$19*Supuestos!$C$25+C6*Supuestos!$C$20*Supuestos!$C$25 -> 7812000 | D11: =D5*Supuestos!$C$19*Supuestos!$C$26+D6*Supuestos!$C$20*Supuestos!$C$26 -> 147420000 | E11: =E5*Supuestos!$C$19*Supuestos!$C$27+E6*Supuestos!$C$20*Supuestos!$C$27 -> 283500000
A12: Margen de contribución | C12: =C10-C11 -> 21530880 | D12: =D10-D11 -> 375580800 | E12: =E10-E11 -> 691740000
A13: Costos fijos | C13: =Supuestos!$C$22 -> 300000000 | D13: =Supuestos!$C$23 -> 700000000 | E13: =Supuestos!$C$24 -> 750000000
A14: EBITDA | C14: =C12-C13 -> -278469120 | D14: =D12-D13 -> -324419200 | E14: =E12-E13 -> -58260000
A15: Margen EBITDA | C15: =IF(C10=0,0,C14/C10) -> -9.4901768 | D15: =IF(D10=0,0,D14/D10) -> -0.62030345 | E15: =IF(E10=0,0,E14/E10) -> -0.059739141
A16: Inversión | C16: =Supuestos!$C$21 -> 920000000 | D16: =0 -> 0 | E16: =0 -> 0
A17: Flujo neto | C17: =C14-C16 -> -1198469120 | D17: =D14-D16 -> -324419200 | E17: =E14-E16 -> -58260000
A18: Flujo acumulado | C18: =C17 -> -1198469120 | D18: =C18+D17 -> -1522888320 | E18: =D18+E17 -> -1581148320
A19: Flujo descontado | C19: =C17/(1+Supuestos!$C$28)^1 -> -1.0421471e+09 | D19: =D17/(1+Supuestos!$C$28)^2 -> -2.4530752e+08 | E19: =E17/(1+Supuestos!$C$28)^3 -> -38306896
A21: Escenario Base | C21: Año 1 | D21: Año 2 | E21: Año 3
A22: SOM: tarjetas 60+ en emisores Credibanco | C22: =Supuestos!$D$6*Supuestos!$D$7 -> 1400000 | D22: =Supuestos!$D$6*Supuestos!$D$7 -> 1400000 | E22: =Supuestos!$D$6*Supuestos!$D$7 -> 1400000
A23: Tarjetas cubiertas por Escudo | C23: =C22*Supuestos!$D$8 -> 70000 | D23: =D22*Supuestos!$D$9 -> 350000 | E23: =E22*Supuestos!$D$10 -> 560000
A24: Tarjetas inscritas en Círculo | C24: =C23*Supuestos!$D$11 -> 2800 | D24: =D23*Supuestos!$D$12 -> 35000 | E24: =E23*Supuestos!$D$13 -> 78400
A25: Ingreso Escudo | C25: =C23*Supuestos!$D$14*Supuestos!$D$25 -> 70000000 | D25: =D23*Supuestos!$D$14*Supuestos!$D$26 -> 1050000000 | E25: =E23*Supuestos!$D$14*Supuestos!$D$27 -> 1680000000
A26: Ingreso Círculo | C26: =C24*Supuestos!$D$15*Supuestos!$D$25 -> 13440000 | D26: =D24*Supuestos!$D$15*Supuestos!$D$26 -> 504000000 | E26: =E24*Supuestos!$D$15*Supuestos!$D$27 -> 1128960000
A27: Ingreso transaccional incremental | C27: =C24*Supuestos!$D$16*Supuestos!$D$17*Supuestos!$D$25*Supuestos!$D$18 -> 2016000 | D27: =D24*Supuestos!$D$16*Supuestos!$D$17*Supuestos!$D$26*Supuestos!$D$18 -> 75600000 | E27: =E24*Supuestos!$D$16*Supuestos!$D$17*Supuestos!$D$27*Supuestos!$D$18 -> 169344000
A28: Ingresos totales | C28: =SUM(C25:C27) -> 85456000 | D28: =SUM(D25:D27) -> 1629600000 | E28: =SUM(E25:E27) -> 2978304000
A29: Costos variables | C29: =C23*Supuestos!$D$19*Supuestos!$D$25+C24*Supuestos!$D$20*Supuestos!$D$25 -> 18480000 | D29: =D23*Supuestos!$D$19*Supuestos!$D$26+D24*Supuestos!$D$20*Supuestos!$D$26 -> 378000000 | E29: =E23*Supuestos!$D$19*Supuestos!$D$27+E24*Supuestos!$D$20*Supuestos!$D$27 -> 712320000
A30: Margen de contribución | C30: =C28-C29 -> 66976000 | D30: =D28-D29 -> 1251600000 | E30: =E28-E29 -> 2265984000
A31: Costos fijos | C31: =Supuestos!$D$22 -> 270000000 | D31: =Supuestos!$D$23 -> 640000000 | E31: =Supuestos!$D$24 -> 680000000
A32: EBITDA | C32: =C30-C31 -> -203024000 | D32: =D30-D31 -> 611600000 | E32: =E30-E31 -> 1585984000
A33: Margen EBITDA | C33: =IF(C28=0,0,C32/C28) -> -2.3757723 | D33: =IF(D28=0,0,D32/D28) -> 0.37530682 | E33: =IF(E28=0,0,E32/E28) -> 0.53251246
A34: Inversión | C34: =Supuestos!$D$21 -> 800000000 | D34: =0 -> 0 | E34: =0 -> 0
A35: Flujo neto | C35: =C32-C34 -> -1003024000 | D35: =D32-D34 -> 611600000 | E35: =E32-E34 -> 1585984000
A36: Flujo acumulado | C36: =C35 -> -1003024000 | D36: =C36+D35 -> -391424000 | E36: =D36+E35 -> 1194560000
A37: Flujo descontado | C37: =C35/(1+Supuestos!$D$28)^1 -> -8.7219478e+08 | D37: =D35/(1+Supuestos!$D$28)^2 -> 4.6245747e+08 | E37: =E35/(1+Supuestos!$D$28)^3 -> 1.0428102e+09
A39: Escenario Optimista | C39: Año 1 | D39: Año 2 | E39: Año 3
A40: SOM: tarjetas 60+ en emisores Credibanco | C40: =Supuestos!$E$6*Supuestos!$E$7 -> 1600000 | D40: =Supuestos!$E$6*Supuestos!$E$7 -> 1600000 | E40: =Supuestos!$E$6*Supuestos!$E$7 -> 1600000
A41: Tarjetas cubiertas por Escudo | C41: =C40*Supuestos!$E$8 -> 128000 | D41: =D40*Supuestos!$E$9 -> 480000 | E41: =E40*Supuestos!$E$10 -> 800000
A42: Tarjetas inscritas en Círculo | C42: =C41*Supuestos!$E$11 -> 6400 | D42: =D41*Supuestos!$E$12 -> 57600 | E42: =E41*Supuestos!$E$13 -> 144000
A43: Ingreso Escudo | C43: =C41*Supuestos!$E$14*Supuestos!$E$25 -> 153600000 | D43: =D41*Supuestos!$E$14*Supuestos!$E$26 -> 1728000000 | E43: =E41*Supuestos!$E$14*Supuestos!$E$27 -> 2880000000
...

Sheet Valor_emisor
A1: ¿Por qué pagaría el emisor? Valor estimado por tarjeta y año (escenario base)
A3: Concepto | B3: Valor | C3: Fuente / lógica
A4: Incidencia anual de fraude en tarjetas 60+ | B4: =0.008 -> 0.008 | C4: Supuesto: 0,8% de tarjetas con un caso al año. Dato clave a pedir al emisor (fraude por edad).
A5: Pérdida promedio por caso (reembolso) | B5: =1800000 -> 1800000 | C5: Supuesto.
A6: Costo operativo por caso (investigación, call center, quejas SFC) | B6: =400000 -> 400000 | C6: Supuesto.
A7: Reducción de fraude con Escudo (reglas) | B7: =0.25 -> 0.25 | C7: Hipótesis H3.
A8: Reducción de fraude con Círculo (alertas + límites + cuidador) | B8: =0.5 -> 0.5 | C8: Hipótesis H3.
A9: Ingreso neto del emisor sobre gasto incremental (intercambio, neto) | B9: =0.01 -> 0.01 | C9: Supuesto.
A10: Valor Escudo por tarjeta cubierta/año | B10: =B4*(B5+B6)*B7 -> 4400 | C10: Fórmula.
A11: Precio Escudo por tarjeta/año (base) | B11: =Supuestos!$D$14*12 -> 3000 | C11: Supuesto de precio.
A12: Relación valor / precio Escudo | B12: =B10/B11 -> 1.4666667 | C12: > 1,0x: el emisor gana.
A13: Valor Círculo por tarjeta inscrita/año | B13: =B4*(B5+B6)*B8+Supuestos!$D$16*Supuestos!$D$17*12*B9 -> 19600 | C13: Fraude evitado + ingreso por mayor uso de la tarjeta.
A14: Precio Círculo por tarjeta/año (base) | B14: =Supuestos!$D$15*12 -> 14400 | C14: Supuesto de precio.
A15: Relación valor / precio Círculo | B15: =B13/B14 -> 1.3611111 | C15: Sin contar retención de la mesada pensional ni reputación.

Sheet Sensibilidad
A1: Sensibilidad del VAN (escenario base, variación ±20% de cada supuesto, COP millones)
A2: Valores calculados con este mismo modelo cambiando un supuesto a la vez (corrida del 18-oct-2026). Para recalcular, cambia el supuesto en la hoja Supuestos.
A4: Supuesto | B4: VAN con −20% | C4: VAN con +20% | D4: Rango
A5: Cobertura de emisores (o participación) | B5: 134 | C5: 1132 | D5: =ABS(C5-B5) -> 998
A6: Precio Escudo | B6: 241 | C6: 1025 | D6: =ABS(C6-B6) -> 784
A7: Precio Círculo | B7: 406 | C7: 860 | D7: =ABS(C7-B7) -> 454
A8: Inscripción al Círculo | B8: 448 | C8: 818 | D8: =ABS(C8-B8) -> 370
A9: Costos fijos | B9: 866 | C9: 400 | D9: =ABS(C9-B9) -> 466
A10: Inversión inicial | B10: 772 | C10: 494 | D10: =ABS(C10-B10) -> 278
A12: VAN base de referencia (COP millones) | B12: =Resumen!C16/1000000 -> 633.07291

Sheet Validacion_datos
A1: Clasificación de los datos iniciales del caso
A3: Enunciado del caso | B3: Clasificación | C3: Qué encontramos | D3: Cómo lo tratamos
A4: 166 M de personas 50+ en ALC en 2024 (25%) y ~280 M (38%) en 2050 (Banco Mundial) | B4: Requiere contrastación | C4: 2050: cobertura del Silver Economy Congress 2026 (Grupo Banco Mundial–España) habla de >280 M (≈40%). 2024: no hallamos la cifra en fuente primaria; IFC usa otras cifras y umbrales. | D4: Solo contexto regional; no entra al business case.
A5: ALC envejece más rápido; Brasil, Colombia, Uruguay, Argentina y Chile en envejecimiento avanzado (UN WPP 2024) | B5: Parcialmente incorrecto | C5: La velocidad de envejecimiento sí la señalan BID y CEPAL. La clasificación por etapas es de CEPAL, no de UN WPP, y ubica a Colombia y Brasil en envejecimiento moderado (Uruguay sí avanzado). | D5: Corregido: Colombia en envejecimiento moderado pero acelerado (en 2036 habrá más 60+ que menores de 15, DANE).
A6: AARP: 50+ = 34% del PIB mundial (~US$45 billones) en 2022; 39% (~US$118 billones) en 2050 | B6: Hecho con error de fecha | C6: Cifras correctas, pero corresponden a 2020 (informe publicado en nov-2022, AARP/Economist Impact). | D6: Corregido el año; dato global, solo contexto. Para Colombia: consumo 50+ ≈ COP 121 billones/año (≈12% del PIB, 2023, prensa).
A7: Las personas mayores son prestatarios más responsables (Banco Mundial) | B7: Interpretación no verificada | C7: No encontramos la fuente primaria. | D7: No se usa: el crédito no es rol de la organización.
A8: 52% de las personas en ALC dice no tener ahorros suficientes para la vejez (WEF) | B8: No verificado | C8: No hallamos el dato en el WEF. Cercanos: CEPAL 2023, 43,4% de los 65+ sin pensión o con pensión bajo la línea de pobreza. | D8: Reemplazado por CEPAL.
A9: DANE: personas mayores = 60+ (Ley 1251 de 2008); 7,1 M (13,9%) en 2021 | B9: Hecho verificado | C9: DANE, nota estadística nov-2021: 7.107.914 personas (13,9%). 2024: ≈15,5%. | D9: Base de la segmentación (60+) y del TAM.
A10: 68% de las personas 60+ en Colombia usa banca móvil o billeteras de forma habitual | B10: Contradicho por fuentes oficiales | C10: DANE 2021: 36,4% de los 65+ tenía acceso a internet y solo 18,1% lo usaba con regularidad. RIF 2024: los 65+ tienen el menor uso de depósitos (≈1 de cada 3). No hallamos el estudio citado. | D10: Descartado. La brecha digital y de confianza es el corazón del problema; por eso la solución es asistida y con familiares.

Sheet Fuentes
A1: Fuentes consultadas (fecha de consulta: 18-oct-2026)
A3: Dato | B3: Fuente | C3: Enlace
A4: Personas 60+ 2021: 7,1 M (13,9%) | B4: DANE, Nota estadística Personas mayores, nov-2021 | C4: https://www.dane.gov.co/ (nota estadística personas mayores 2021)
A5: Acceso a internet 65+ (36,4%) y uso regular (18,1%), 2021 | B5: DANE citado por Alcaldía de Bogotá | C5: https://bogota.gov.co/en/node/209419
A6: Inclusión financiera por edad (65+ menor uso de depósitos) | B6: Banca de las Oportunidades y SFC, Reporte de Inclusión Financiera 2024 | C6: https://www.superfinanciera.gov.co/publicaciones/10115642/
A7: Indicadores 2025 (acceso a depósitos 96,5%) | B7: Banca de las Oportunidades, presentación RIF 2025 (ago-2026) | C7: https://www.bancadelasoportunidades.gov.co/sites/default/files/2026-08/presentacion-rif_2025.pdf
A8: Pensionados: 2.111.953 (1,75 M RPM; 0,36 M RAIS) | B8: Superintendencia Financiera vía Valora Analitik | C8: https://www.valoraanalitik.com/pensionados-colombia-reportan-importante-aumento/
A9: Colombia Mayor: 1,6 M beneficiarios; meta pilar solidario 3,1 M | B9: Prosperidad Social vía Portafolio | C9: https://www.portafolio.co/economia/gobierno/mayores-en-pobreza-como-la-reforma-pensional-busca-apoyar-con-un-bono-mensual-638237
A10: Efectivo ≈78% de las transacciones | B10: Banco de la República, encuesta de instrumentos de pago | C10: https://www.banrep.gov.co/es/estabilidad-financiera/encuesta-percepcion-uso-instrumentos-pagos/2024
A11: Tarjetas: 50,2 M débito y 16,7 M crédito (2025) | B11: SFC vía prensa | C11: https://www.larepublica.co/finanzas/bancos-con-mas-tarjetas-de-creditos-4084190
A12: Credibanco 2024: COP 130 billones procesados; ~300.000 puntos de acceso | B12: Portafolio (entrevista al presidente de Credibanco) | C12: https://www.portafolio.co/economia/finanzas/asi-se-prepara-credibanco-para-participar-en-la-implementacion-de-bre-b-625141
A13: Credibanco integrado a Bre-B | B13: Valora Analitik | C13: https://www.valoraanalitik.com/credibanco-se-integra-a-bre-b-el-nuevo-sistema-de-pagos-inmediatos-del-banco-de-la-republica/
A14: Bre-B: >500 M transacciones en 5 meses | B14: El Tiempo (ACI Worldwide) | C14: https://www.eltiempo.com/economia/sector-financiero/bre-b-consolida-la-digitalizacion-financiera-y-proyecta-el-salto-hacia-pagos-transfronterizos-en-tiempo-real-3541842
... A20: Llamadas fraudulentas afectan principalmente a adultos mayores | B20: Banco de Bogotá vía Portafolio | C20: https://www.portafolio.co/tecnologia/banco-de-bogota-advierte-sobre-el-aumento-de-fraudes-digitales-y-de-una-modalidad-de-estafa-que-esta-creciendo-501757
